{"uuid": "67d204e2-c7f1-4e96-bff2-63d2117f73e7", "children": ["9bc54801-2b8f-4687-99bc-2a4700e9af1c", "27102d9d-614e-4546-8e93-aa5a88a7d41e"], "befores": [{"name": "database_base_configuration", "status": "broken", "statusDetails": {"message": "pymysql.err.OperationalError: (2003, \"Can't connect to MySQL server on '10.66.8.200' ([WinError 10065] 套接字操作尝试一个无法连接的主机。)\")\n", "trace": "  File \"c:\\users\\keda\\appdata\\local\\programs\\python\\python36\\lib\\site-packages\\pluggy\\callers.py\", line 187, in _multicall\n    res = hook_impl.function(*args)\n  File \"c:\\users\\keda\\appdata\\local\\programs\\python\\python36\\lib\\site-packages\\_pytest\\fixtures.py\", line 957, in pytest_fixture_setup\n    result = call_fixture_func(fixturefunc, request, kwargs)\n  File \"c:\\users\\keda\\appdata\\local\\programs\\python\\python36\\lib\\site-packages\\_pytest\\fixtures.py\", line 787, in call_fixture_func\n    res = fixturefunc(**kwargs)\n  File \"E:\\automatic\\ui-automatic\\test_cases\\conftest.py\", line 10, in database_base_configuration\n    delete_database_data_test_ci()\n  File \"c:\\users\\keda\\appdata\\local\\programs\\python\\python36\\lib\\site-packages\\allure_commons\\_allure.py\", line 157, in impl\n    return func(*a, **kw)\n  File \"E:\\automatic\\ui-automatic\\Utils\\operateDatabaseData.py\", line 31, in delete_database_data_test_ci\n    db=db_name)\n  File \"c:\\users\\keda\\appdata\\local\\programs\\python\\python36\\lib\\site-packages\\pymysql\\__init__.py\", line 94, in Connect\n    return Connection(*args, **kwargs)\n  File \"c:\\users\\keda\\appdata\\local\\programs\\python\\python36\\lib\\site-packages\\pymysql\\connections.py\", line 325, in __init__\n    self.connect()\n  File \"c:\\users\\keda\\appdata\\local\\programs\\python\\python36\\lib\\site-packages\\pymysql\\connections.py\", line 630, in connect\n    raise exc\n"}, "steps": [{"name": "清空数据库", "status": "broken", "statusDetails": {"message": "pymysql.err.OperationalError: (2003, \"Can't connect to MySQL server on '10.66.8.200' ([WinError 10065] 套接字操作尝试一个无法连接的主机。)\")\n", "trace": "  File \"c:\\users\\keda\\appdata\\local\\programs\\python\\python36\\lib\\site-packages\\allure_commons\\_allure.py\", line 157, in impl\n    return func(*a, **kw)\n  File \"E:\\automatic\\ui-automatic\\Utils\\operateDatabaseData.py\", line 31, in delete_database_data_test_ci\n    db=db_name)\n  File \"c:\\users\\keda\\appdata\\local\\programs\\python\\python36\\lib\\site-packages\\pymysql\\__init__.py\", line 94, in Connect\n    return Connection(*args, **kwargs)\n  File \"c:\\users\\keda\\appdata\\local\\programs\\python\\python36\\lib\\site-packages\\pymysql\\connections.py\", line 325, in __init__\n    self.connect()\n  File \"c:\\users\\keda\\appdata\\local\\programs\\python\\python36\\lib\\site-packages\\pymysql\\connections.py\", line 630, in connect\n    raise exc\n"}, "start": 1578028788642, "stop": 1578028788658}], "start": 1578028788642, "stop": 1578028788658}], "start": 1578028788642, "stop": 1578028788767}