{"uuid": "71bc0035-b681-4300-bdf4-61985effc6f4", "children": ["f8fee22f-0990-48e2-826e-bfe008fc0cce"], "befores": [{"name": "normal_login", "status": "broken", "statusDetails": {"message": "selenium.common.exceptions.TimeoutException: Message: timeout\n  (Session info: chrome=70.0.3538.67 Chrome-keda/70.0.3538.67.20190402)\n  (Driver info: chromedriver=2.41,platform=Windows NT 10.0.18362 x86_64)\n\n", "trace": "  File \"c:\\users\\keda\\appdata\\local\\programs\\python\\python36\\lib\\site-packages\\pluggy\\callers.py\", line 187, in _multicall\n    res = hook_impl.function(*args)\n  File \"c:\\users\\keda\\appdata\\local\\programs\\python\\python36\\lib\\site-packages\\_pytest\\fixtures.py\", line 957, in pytest_fixture_setup\n    result = call_fixture_func(fixturefunc, request, kwargs)\n  File \"c:\\users\\keda\\appdata\\local\\programs\\python\\python36\\lib\\site-packages\\_pytest\\fixtures.py\", line 787, in call_fixture_func\n    res = fixturefunc(**kwargs)\n  File \"E:\\automatic\\ui-automatic\\test_cases\\test_user_management\\test_add_user\\conftest.py\", line 30, in normal_login\n    state_login_class.get_login_url()\n  File \"c:\\users\\keda\\appdata\\local\\programs\\python\\python36\\lib\\site-packages\\allure_commons\\_allure.py\", line 157, in impl\n    return func(*a, **kw)\n  File \"E:\\automatic\\ui-automatic\\OperationalLayer\\Login\\login.py\", line 18, in get_login_url\n    self.get_url()\n  File \"E:\\automatic\\ui-automatic\\Base\\base.py\", line 59, in get_url\n    return self.driver.get(self.url)\n  File \"c:\\users\\keda\\appdata\\local\\programs\\python\\python36\\lib\\site-packages\\selenium\\webdriver\\remote\\webdriver.py\", line 333, in get\n    self.execute(Command.GET, {'url': url})\n  File \"c:\\users\\keda\\appdata\\local\\programs\\python\\python36\\lib\\site-packages\\selenium\\webdriver\\remote\\webdriver.py\", line 321, in execute\n    self.error_handler.check_response(response)\n  File \"c:\\users\\keda\\appdata\\local\\programs\\python\\python36\\lib\\site-packages\\selenium\\webdriver\\remote\\errorhandler.py\", line 242, in check_response\n    raise exception_class(message, screen, stacktrace)\n"}, "steps": [{"name": "到达登录页面", "status": "broken", "statusDetails": {"message": "selenium.common.exceptions.TimeoutException: Message: timeout\n  (Session info: chrome=70.0.3538.67 Chrome-keda/70.0.3538.67.20190402)\n  (Driver info: chromedriver=2.41,platform=Windows NT 10.0.18362 x86_64)\n\n", "trace": "  File \"c:\\users\\keda\\appdata\\local\\programs\\python\\python36\\lib\\site-packages\\allure_commons\\_allure.py\", line 157, in impl\n    return func(*a, **kw)\n  File \"E:\\automatic\\ui-automatic\\OperationalLayer\\Login\\login.py\", line 18, in get_login_url\n    self.get_url()\n  File \"E:\\automatic\\ui-automatic\\Base\\base.py\", line 59, in get_url\n    return self.driver.get(self.url)\n  File \"c:\\users\\keda\\appdata\\local\\programs\\python\\python36\\lib\\site-packages\\selenium\\webdriver\\remote\\webdriver.py\", line 333, in get\n    self.execute(Command.GET, {'url': url})\n  File \"c:\\users\\keda\\appdata\\local\\programs\\python\\python36\\lib\\site-packages\\selenium\\webdriver\\remote\\webdriver.py\", line 321, in execute\n    self.error_handler.check_response(response)\n  File \"c:\\users\\keda\\appdata\\local\\programs\\python\\python36\\lib\\site-packages\\selenium\\webdriver\\remote\\errorhandler.py\", line 242, in check_response\n    raise exception_class(message, screen, stacktrace)\n"}, "start": 1583139380258, "stop": 1583150180898}], "start": 1583139380258, "stop": 1583150180902}], "start": 1583139380258, "stop": 1583196974262}